In Next.js 15, a subtle issue can arise when using server components with `async/await` within a loop. If an error occurs during one iteration, the loop might not stop gracefully, leading to unexpected behavior or silent failures. This is because the `async/await` in the loop won't naturally halt on error. For example:

```javascript
// pages/api/data.js (Server Component)
export default async function handler() {
  const dataPromises = [Promise.resolve(1), Promise.reject('Error!'), Promise.resolve(3)];

  const results = [];
  for (const promise of dataPromises) {
    try {
      const result = await promise;
      results.push(result);
    } catch (error) {
      console.error('Error fetching data:', error);
      //Loop continues despite the error
    }
  }
  return results; // Returns [1, 3] - Error ignored
}
```
This code will silently swallow errors.  The `catch` block logs the error, but the loop continues.  The `results` array will only contain values that processed successfully. 